<?xml version='1.0'?>

<robot name="myrobot" xmlns:xacro="http://www.ros.org/wiki/xacro">

    <xacro:property name="cameraSize" value="0.05" />
    <xacro:property name="cameraMass" value="0.1" />

    <link name='chassis'>
        <pose>0 0 0.1 0 0 0</pose>

        <inertial>
            <mass value="15.0" />
            <origin xyz="0.0 0 0.1" rpy=" 0 0 0" />
            <inertia
                ixx="0.1" ixy="0" ixz="0"
                iyy="0.1" iyz="0"
                izz="0.1"
            />
        </inertial>

        <collision name='collision'>
            <geometry>
                <box size=".4 .2 .1" />
            </geometry>
        </collision>

        <visual name='chassis_visual'>
            <origin xyz="0 0 0" rpy=" 0 0 0" />
            <geometry>
                <box size=".4 .2 .1" />
            </geometry>
        </visual>


    </link>


    <!-- Back wheel -->
    <link name="left_wheel">
        <!--origin
        xyz="0.1 0.13 0.1" rpy="0 1.5707 1.5707"/-->
        <collision name="collision">
            <origin xyz="0 0 0" rpy="0 1.5707 1.5707" />
            <geometry>
                <cylinder radius="0.1" length="0.05" />
            </geometry>
        </collision>
        <visual name="left_wheel_visual">
            <origin xyz="0 0 0" rpy="0 1.5707 1.5707" />
            <geometry>
                <cylinder radius="0.1" length="0.05" />
            </geometry>
        </visual>
        <inertial>
            <origin xyz="0 0 0" rpy="0 1.5707 1.5707" />
            <mass value="5" />
            <inertia
                ixx=".1" ixy="0.0" ixz="0.0"
                iyy=".1" iyz="0.0"
                izz=".1" />
        </inertial>
    </link>

    <link name="right_wheel">
        <!--origin
        xyz="0.1 -0.13 0.1" rpy="0 1.5707 1.5707"/-->
        <collision name="collision">
            <origin xyz="0 0 0" rpy="0 1.5707 1.5707" />
            <geometry>
                <cylinder radius="0.1" length="0.05" />
            </geometry>
        </collision>
        <visual name="right_wheel_visual">
            <origin xyz="0 0 0" rpy="0 1.5707 1.5707" />
            <geometry>
                <cylinder radius="0.1" length="0.05" />
            </geometry>
        </visual>
        <inertial>
            <origin xyz="0 0 0" rpy="0 1.5707 1.5707" />
            <mass value="5" />
            <inertia
                ixx=".1" ixy="0.0" ixz="0.0"
                iyy=".1" iyz="0.0"
                izz=".1" />
        </inertial>
    </link>


    <joint type="continuous" name="left_wheel_hinge">
        <origin xyz="-0.2 0.15 0" rpy="0 0 0" />
        <!--origin
        xyz="0.1 0.13 0" rpy="0 1.5707 1.5707"/-->
        <child link="left_wheel" />
        <parent link="chassis" />
        <axis xyz="0 1 0" rpy="0 0 0" />
        <limit effort="10000" velocity="1000" />
        <joint_properties damping="1.0" friction="1.0" />
    </joint>

    <joint type="continuous" name="right_wheel_hinge">
        <origin xyz="-0.2 -0.15 0" rpy="0 0 0" />
        <!--origin
        xyz="0.1 -0.13 0" rpy="0 1.5707 1.5707"/-->
        <child link="right_wheel" />
        <parent link="chassis" />
        <axis xyz="0 1 0" rpy="0 0 0" />
        <limit effort="10000" velocity="1000" />
        <joint_properties damping="1.0" friction="1.0" />
    </joint>

    <!-- Front wheel -->
    <link name="front_left_wheel">
        <!--origin
        xyz="0.1 0.13 0.1" rpy="0 1.5707 1.5707"/-->
        <collision name="collision">
            <origin xyz="0 0 0" rpy="0 1.5707 1.5707" />
            <geometry>
                <cylinder radius="0.1" length="0.05" />
            </geometry>
        </collision>
        <visual name="left_wheel_visual">
            <origin xyz="0 0 0" rpy="0 1.5707 1.5707" />
            <geometry>
                <cylinder radius="0.1" length="0.05" />
            </geometry>
        </visual>
        <inertial>
            <origin xyz="0 0 0" rpy="0 1.5707 1.5707" />
            <mass value="5" />
            <inertia
                ixx=".1" ixy="0.0" ixz="0.0"
                iyy=".1" iyz="0.0"
                izz=".1" />
        </inertial>
    </link>

    <link name="front_right_wheel">
        <!--origin
        xyz="0.1 -0.13 0.1" rpy="0 1.5707 1.5707"/-->
        <collision name="collision">
            <origin xyz="0 0 0" rpy="0 1.5707 1.5707" />
            <geometry>
                <cylinder radius="0.1" length="0.05" />
            </geometry>
        </collision>
        <visual name="right_wheel_visual">
            <origin xyz="0 0 0" rpy="0 1.5707 1.5707" />
            <geometry>
                <cylinder radius="0.1" length="0.05" />
            </geometry>
        </visual>
        <inertial>
            <origin xyz="0 0 0" rpy="0 1.5707 1.5707" />
            <mass value="5" />
            <inertia
                ixx=".1" ixy="0.0" ixz="0.0"
                iyy=".1" iyz="0.0"
                izz=".1" />
        </inertial>
    </link>

    <!-- Front Steer -->
    <link name="front_left_steer">
        <!--origin
        xyz="0.1 0.13 0.1" rpy="0 1.5707 1.5707"/-->
        <collision name="collision">
            <origin xyz="0 0 0" rpy="0 0 0" />
            <geometry>
                <cylinder radius="0.01" length="0.2" />
            </geometry>
        </collision>
        <visual name="left_steer_visual">
            <origin xyz="0 0 0" rpy="0 0 0" />
            <geometry>
                <cylinder radius="0.01" length="0.2" />
            </geometry>
        </visual>
        <inertial>
            <origin xyz="0 0 0" rpy="0 0 0" />
            <mass value="5" />
            <inertia
                ixx=".1" ixy="0.0" ixz="0.0"
                iyy=".1" iyz="0.0"
                izz=".1" />
        </inertial>
    </link>

    <link name="front_right_steer">
        <!--origin
        xyz="0.1 -0.13 0.1" rpy="0 1.5707 1.5707"/-->
        <collision name="collision">
            <origin xyz="0 0 0" rpy="0 0 0" />
            <geometry>
                <cylinder radius="0.01" length="0.2" />
            </geometry>
        </collision>
        <visual name="right_steer_visual">
            <origin xyz="0 0 0" rpy="0 0 0" />
            <geometry>
                <cylinder radius="0.01" length="0.2" />
            </geometry>
        </visual>
        <inertial>
            <origin xyz="0 0 0" rpy="0 0 0" />
            <mass value="5" />
            <inertia
                ixx=".1" ixy="0.0" ixz="0.0"
                iyy=".1" iyz="0.0"
                izz=".1" />
        </inertial>
    </link>

    <joint type="continuous" name="front_left_wheel_hinge">
        <origin xyz="0.0 0.0 -0.1" rpy="0 0 0" />
        <!--origin
        xyz="0.1 0.13 0" rpy="0 1.5707 1.5707"/-->
        <child link="front_left_wheel" />
        <parent link="front_left_steer" />
        <axis xyz="0 1 0" rpy="0 0 0" />
        <limit effort="10000" velocity="1000" />
        <joint_properties damping="1.0" friction="1.0" />
    </joint>

    <joint type="continuous" name="front_right_wheel_hinge">
        <origin xyz="0. 0 -0.1" rpy="0 0 0" />
        <!--origin
        xyz="0.1 -0.13 0" rpy="0 1.5707 1.5707"/-->
        <child link="front_right_wheel" />
        <parent link="front_right_steer" />
        <axis xyz="0 1 0" rpy="0 0 0" />
        <limit effort="10000" velocity="1000" />
        <joint_properties damping="1.0" friction="1.0" />
    </joint>

    <joint type="continuous" name="front_left_steer_hinge">
        <origin xyz="0.2 0.15 0.1" rpy="0 0 0" />
        <!--origin
        xyz="0.1 0.13 0" rpy="0 1.5707 1.5707"/-->
        <child link="front_left_steer" />
        <parent link="chassis" />
        <axis xyz="0 0 1" />
    </joint>

    <joint type="continuous" name="front_right_steer_hinge">
        <origin xyz="0.2 -0.15 0.1" rpy="0 0 0" />
        <!--origin
        xyz="0.1 -0.13 0" rpy="0 1.5707 1.5707"/-->
        <child link="front_right_steer" />
        <parent link="chassis" />
        <axis xyz="0 0 1" />
    </joint>

    <!-- Sensor links and fixed joints -->
    <link name="center_laser_link">
        <visual>
            <geometry>
                <cylinder length="0.015" radius="0.01" />
            </geometry>
        </visual>

        <collision>
            <geometry>
                <cylinder length="0.35" radius="0.1" />
            </geometry>
        </collision>
        <inertial>
            <mass value="0.001" />
            <inertia ixx="0.000001" ixy="0.0" ixz="0.0" iyy="0.000001" iyz="0.0" izz="0.000001" />
        </inertial>
    </link>
    <joint name="center_laser_joint" type="fixed">
        <parent link="chassis" />
        <child link="center_laser_link" />
        <origin xyz="0 0.0 0.2" rpy="0 0 -3.1415" />
    </joint>


    <link name="camera">
        <collision>
            <origin xyz="0 0 0" rpy="0 0 0" />
            <geometry>
                <box size="${cameraSize} ${cameraSize} ${cameraSize}" />
            </geometry>
        </collision>

        <visual>
            <origin xyz="0 0 0" rpy="0 0 0" />
            <geometry>
                <box size="${cameraSize} ${cameraSize} ${cameraSize}" />
            </geometry>
            <material name="green" />
        </visual>

        <inertial>
            <mass value="${cameraMass}" />
            <origin xyz="0 0 0" rpy="0 0 0" />
            <box_inertia m="${cameraMass}" x="${cameraSize}" y="${cameraSize}" z="${cameraSize}" />
            <inertia ixx="1e-6" ixy="0" ixz="0" iyy="1e-6" iyz="0" izz="1e-6" />
        </inertial>
    </link>

    <joint name="camera_joint" type="fixed">
        <axis xyz="0 1 0" />
        <origin xyz=".2 0 0" rpy="0 0 0" />
        <parent link="chassis" />
        <child link="camera" />
    </joint>


    <joint name="hokuyo_joint" type="fixed">
        <axis xyz="0 1 0" />
        <origin xyz=".15 0 .1" rpy="0 0 0" />
        <parent link="chassis" />
        <child link="hokuyo" />
    </joint>

    <!-- Hokuyo Laser -->
    <link name="hokuyo">
        <collision>
            <origin xyz="0 0 0" rpy="0 0 0" />
            <geometry>
                <box size="0.1 0.1 0.1" />
            </geometry>
        </collision>

        <visual>
            <origin xyz="0 0 0" rpy="0 0 0" />
            <geometry>
                <mesh filename="package://osiris_bot/meshes/hokuyo.dae" />
            </geometry>
        </visual>

        <inertial>
            <mass value="1e-5" />
            <origin xyz="0 0 0" rpy="0 0 0" />
            <inertia ixx="1e-6" ixy="0" ixz="0" iyy="1e-6" iyz="0" izz="1e-6" />
        </inertial>
    </link>

</robot>
